<?xml version="1.0" encoding="utf-8"?>
<!-- This URDF was automatically created by SolidWorks to URDF Exporter! Originally created by Stephen Brawner (brawner@gmail.com) 
     Commit Version: 1.6.0-1-g15f4949  Build Version: 1.6.7594.29634
     For more information, please see http://wiki.ros.org/sw_urdf_exporter -->
<robot
  name="Assem1">


  <link
    name="truck_body">
    <inertial>
      <origin
        xyz="-0.067633 -0.0127 -0.00012836"
        rpy="0 0 0" />
      <mass
        value="50.32569" />
      <inertia
        ixx="0.00034762"
        ixy="-9.1908E-22"
        ixz="-2.0837E-06"
        iyy="0.00092476"
        iyz="-3.9642E-21"
        izz="0.00061217" />
    </inertial>
    <visual>
      <origin
        xyz="0 0 0"
        rpy="0 0 0" />
      <geometry>
        <mesh
          filename="package://Assem1/meshes/truck_body.STL" />
      </geometry>
      <material
        name="">
        <color
          rgba="0.79216 0.81961 0.93333 1" />
      </material>
    </visual>
    <collision>
      <origin
        xyz="0 0 0"
        rpy="0 0 0" />
      <geometry>
        <mesh
          filename="package://Assem1/meshes/truck_body.STL" />
      </geometry>
      <surface>
        <friction>
          <ode>
            <mu>0</mu>
            <mu2>0</mu2>
            <slip1>1.0</slip1>
            <slip2>1.0</slip2>
          </ode>
        </friction>
      </surface>
    </collision>
  </link>
  <link
    name="front_wheel">
    <inertial>
      <origin
        xyz="0 0 -0.0127"
        rpy="0 0 0" />
      <mass
        value="50.11583" />
      <inertia
        ixx="4.8264E-05"
        ixy="0"
        ixz="7.8626E-38"
        iyy="4.8264E-05"
        iyz="-1.0831E-37"
        izz="8.4072E-05" />
    </inertial>
    <visual>
      <origin
        xyz="0 0 0"
        rpy="0 0 0" />
      <geometry>
        <mesh
          filename="package://Assem1/meshes/front_wheel.STL" />
      </geometry>
      <material
        name="">
        <color
          rgba="0.79216 0.81961 0.93333 1" />
      </material>
    </visual>
    <collision>
      <origin
        xyz="0 0 0"
        rpy="0 0 0" />
      <geometry>
        <mesh
          filename="package://Assem1/meshes/front_wheel.STL" />
      </geometry>
      <surface>
        <friction>
          <ode>
            <mu>0</mu>
            <mu2>0</mu2>
            <slip1>1.0</slip1>
            <slip2>1.0</slip2>
          </ode>
        </friction>
      </surface>
    </collision>
  </link>
  <joint
    name="joint1"
    type="continuous">
    <origin
      xyz="-0.127 -0.0127 0.0127"
      rpy="0 0 0" />
    <parent
      link="truck_body" />
    <child
      link="front_wheel" />
    <axis
      xyz="0 0 1" />
    <limit
      effort="1"
      velocity="1" />
  </joint>
  <link
    name="rear_left_wheel">
    <inertial>
      <origin
        xyz="0 0 -0.0127"
        rpy="0 0 0" />
      <mass
        value="50.11583" />
      <inertia
        ixx="4.8264E-05"
        ixy="-8.1566E-53"
        ixz="7.1715E-22"
        iyy="4.8264E-05"
        iyz="-1.0831E-37"
        izz="8.4072E-05" />
    </inertial>
    <visual>
      <origin
        xyz="0 0 0"
        rpy="0 0 0" />
      <geometry>
        <mesh
          filename="package://Assem1/meshes/rear_left_wheel.STL" />
      </geometry>
      <material
        name="">
        <color
          rgba="0.79216 0.81961 0.93333 1" />
      </material>
    </visual>
    <collision>
      <origin
        xyz="0 0 0"
        rpy="0 0 0" />
      <geometry>
        <mesh
          filename="package://Assem1/meshes/rear_left_wheel.STL" />
      </geometry>
      <surface>
        <friction>
          <ode>
            <mu>0</mu>
            <mu2>0</mu2>
            <slip1>1.0</slip1>
            <slip2>1.0</slip2>
          </ode>
        </friction>
      </surface>
    </collision>
  </link>
  <joint
    name="joint2"
    type="continuous">
    <origin
      xyz="-0.0254 -0.021138 0.0762"
      rpy="0 0 0" />
    <parent
      link="truck_body" />
    <child
      link="rear_left_wheel" />
    <axis
      xyz="0 0 1" />
    <limit
      effort="1"
      velocity="1" />
  </joint>
  <link
    name="rear_right_wheel">
    <inertial>
      <origin
        xyz="0 0 0.0127"
        rpy="0 0 0" />
      <mass
        value="50.11583" />
      <inertia
        ixx="4.8264E-05"
        ixy="-8.1566E-53"
        ixz="7.1715E-22"
        iyy="4.8264E-05"
        iyz="-1.0831E-37"
        izz="8.4072E-05" />
    </inertial>
    <visual>
      <origin
        xyz="0 0 0"
        rpy="0 0 0" />
      <geometry>
        <mesh
          filename="package://Assem1/meshes/rear_right_wheel.STL" />
      </geometry>
      <material
        name="">
        <color
          rgba="0.79216 0.81961 0.93333 1" />
      </material>
    </visual>
    <collision>
      <origin
        xyz="0 0 0"
        rpy="0 0 0" />
      <geometry>
        <mesh
          filename="package://Assem1/meshes/rear_right_wheel.STL" />
      </geometry>
      <surface>
        <friction>
          <ode>
            <mu>0</mu>
            <mu2>0</mu2>
            <slip1>1.0</slip1>
            <slip2>1.0</slip2>
          </ode>
        </friction>
      </surface>
    </collision>
  </link>
  <joint
    name="joint3"
    type="continuous">
    <origin
      xyz="-0.0254 -0.021138 -0.0762"
      rpy="0 0 0" />
    <parent
      link="truck_body" />
    <child
      link="rear_right_wheel" />
    <axis
      xyz="0 0 1" />
    <limit
      effort="1"
      velocity="1" />
  </joint>


  <transmission name="tran1">
    <type>transmission_interface/SimpleTransmission</type>
    <joint name="joint1">
      <hardwareInterface>hardware_interface/EffortJointInterface</hardwareInterface>
    </joint>
    <actuator name="motor1">
      <hardwareInterface>hardware_interface/EffortJointInterface</hardwareInterface>
      <mechanicalReduction>1</mechanicalReduction>
    </actuator>
  </transmission>

  <transmission name="tran2">
    <type>transmission_interface/SimpleTransmission</type>
    <joint name="joint2">
      <hardwareInterface>hardware_interface/EffortJointInterface</hardwareInterface>
    </joint>
    <actuator name="motor2">
      <hardwareInterface>hardware_interface/EffortJointInterface</hardwareInterface>
      <mechanicalReduction>1</mechanicalReduction>
    </actuator>
  </transmission>

  <transmission name="tran3">
    <type>transmission_interface/SimpleTransmission</type>
    <joint name="joint3">
      <hardwareInterface>hardware_interface/EffortJointInterface</hardwareInterface>
    </joint>
    <actuator name="motor3">
      <hardwareInterface>hardware_interface/EffortJointInterface</hardwareInterface>
      <mechanicalReduction>1</mechanicalReduction>
    </actuator>
  </transmission>

  <gazebo>
    <plugin name="gazebo_ros_control" filename="libgazebo_ros_control.so">
      <robotNamespace>/Assem1</robotNamespace>
      <robotSimType>gazebo_ros_control/DefaultRobotHWSim</robotSimType>
    </plugin>
  </gazebo>
</robot>